<?xml version="1.0" ?>
<sdf version="1.8">

    <model name='r0' canonical_link='chassis_r0'>
        <!-- <pose relative_to='world'>0 0 0 0 0 0</pose>   the pose is relative to the world by default -->

        <frame name="lidar_r0_frame" attached_to='chassis_r0'>
            <pose>0.8 0 0.5 0 0 0</pose>
        </frame>
        <link name='chassis_r0'>
            <pose relative_to='__model__'>0.5 0 0.4 0 0 0</pose>
            <inertial> <!--inertial properties of the link mass, inertia matix-->
                <mass>1.14395</mass>
                <inertia>
                    <ixx>0.126164</ixx>
                    <ixy>0</ixy>
                    <ixz>0</ixz>
                    <iyy>0.416519</iyy>
                    <iyz>0</iyz>
                    <izz>0.481014</izz>
                </inertia>
            </inertial>
            <visual name='visual'>
                <geometry>
                    <box>
                        <size>2.0 1.0 0.5</size> <!--question: this size is in meter-->
                    </box>
                </geometry>
                <!--let's add color to our link-->
                <material>
                    <ambient>0.0 0.0 1.0 1</ambient>
                    <diffuse>0.0 0.0 1.0 1</diffuse>
                    <specular>0.0 0.0 1.0 1</specular>
                </material>
            </visual>
            <collision name='collision'> <!--todo: describe why we need the collision-->
                <geometry>
                    <box>
                        <size>2.0 1.0 0.5</size>
                    </box>
                </geometry>
            </collision>
            <sensor name='gpu_lidar_r0' type='gpu_lidar'>"
                <pose relative_to='lidar_r0_frame'>0 0 0 0 0 0</pose>
                <topic>/r0/lidar</topic>
                <update_rate>10</update_rate>
                <ray>
                    <scan>
                        <horizontal>
                        <samples>640</samples>
                        <resolution>1</resolution>
                        <min_angle>-1.396263</min_angle>
                        <max_angle>1.396263</max_angle>
                        </horizontal>
                        <vertical>
                        <samples>1</samples>
                        <resolution>0.01</resolution>
                        <min_angle>0</min_angle>
                        <max_angle>0</max_angle>
                        </vertical>
                    </scan>
                <range>
                    <min>0.08</min>
                    <max>10.0</max>
                    <resolution>0.01</resolution>
                </range>
                </ray>
                <always_on>1</always_on>
                <visualize>true</visualize>
            </sensor> 
        </link>

        <!--let's build the left wheel-->
        <link name='left_wheel_r0'>
            <pose relative_to="chassis_r0">-0.5 0.6 0 -1.5707 0 0</pose> <!--angles are in radian-->
            <inertial>
                <mass>2</mass>
                <inertia>
                    <ixx>0.145833</ixx>
                    <ixy>0</ixy>
                    <ixz>0</ixz>
                    <iyy>0.145833</iyy>
                    <iyz>0</iyz>
                    <izz>0.125</izz>
                </inertia>
            </inertial>
            <visual name='visual'>
                <geometry>
                    <cylinder>
                        <radius>0.4</radius>
                        <length>0.2</length>
                    </cylinder>
                </geometry>
                <material>
                    <ambient>1.0 0.0 0.0 1</ambient>
                    <diffuse>1.0 0.0 0.0 1</diffuse>
                    <specular>1.0 0.0 0.0 1</specular>
                </material>
            </visual>
            <collision name='collision'>
                <geometry>
                    <cylinder>
                        <radius>0.4</radius>
                        <length>0.2</length>
                    </cylinder>
                </geometry>
            </collision>
        </link>

        <!--copy and paste for right wheel but change position-->
        <link name='right_wheel_r0'>
            <pose relative_to="chassis_r0">-0.5 -0.6 0 -1.5707 0 0</pose> <!--angles are in radian-->
            <inertial>
                <mass>1</mass>
                <inertia>
                    <ixx>0.145833</ixx>
                    <ixy>0</ixy>
                    <ixz>0</ixz>
                    <iyy>0.145833</iyy>
                    <iyz>0</iyz>
                    <izz>0.125</izz>
                </inertia>
            </inertial>
            <visual name='visual'>
                <geometry>
                    <cylinder>
                        <radius>0.4</radius>
                        <length>0.2</length>
                    </cylinder>
                </geometry>
                <material>
                    <ambient>1.0 0.0 0.0 1</ambient>
                    <diffuse>1.0 0.0 0.0 1</diffuse>
                    <specular>1.0 0.0 0.0 1</specular>
                </material>
            </visual>
            <collision name='collision'>
                <geometry>
                    <cylinder>
                        <radius>0.4</radius>
                        <length>0.2</length>
                    </cylinder>
                </geometry>
            </collision>
        </link>

        <frame name="caster_r0_frame" attached_to='chassis_r0'>
            <pose>0.8 0 -0.2 0 0 0</pose>
        </frame>

        <!--caster wheel-->
        <link name='caster_r0'>
            <pose relative_to='caster_r0_frame'/>
            <inertial>
                <mass>1</mass>
                <inertia>
                    <ixx>0.1</ixx>
                    <ixy>0</ixy>
                    <ixz>0</ixz>
                    <iyy>0.1</iyy>
                    <iyz>0</iyz>
                    <izz>0.1</izz>
                </inertia>
            </inertial>
            <visual name='visual'>
                <geometry>
                    <sphere>
                        <radius>0.2</radius>
                    </sphere>
                </geometry>
                <material>
                    <ambient>0.0 1 0.0 1</ambient>
                    <diffuse>0.0 1 0.0 1</diffuse>
                    <specular>0.0 1 0.0 1</specular>
                </material>
            </visual>
            <collision name='collision'>
                <geometry>
                    <sphere>
                        <radius>0.2</radius>
                    </sphere>
                </geometry>
            </collision>
        </link>

        <link name="rgbd_camera">
            <pose relative_to="__model__">1.5 0 0.75 0 0.785 0</pose> 
            <inertial>
                <mass>0.1</mass>
                <inertia>
                    <ixx>0.000166667</ixx>
                    <iyy>0.000166667</iyy>
                    <izz>0.000166667</izz>
                </inertia>
            </inertial>
            <collision name="collision">
                <geometry>
                    <box>
                        <size>0.1 0.1 0.1</size>
                    </box>
                </geometry>
            </collision>
            <visual name="visual">
                <geometry>
                    <box>
                        <size>0.1 0.1 0.1</size>
                    </box>
                </geometry>
            </visual>
            <sensor name="rgbd_camera" type="rgbd_camera">
            <camera>
                <horizontal_fov>1.047</horizontal_fov>
                <image>
                    <width>320</width>
                    <height>240</height>
                </image>
                <clip>
                    <near>0.1</near>
                    <far>100</far>
                </clip>
            </camera>
            <always_on>1</always_on>
            <update_rate>30</update_rate>
            <visualize>true</visualize>
            <!-- <topic>/r0/rgbd_camera</topic> -->
            <enable_metrics>true</enable_metrics>
            </sensor>
        </link>

        <joint name='camera_joint_r0' type='fixed'>
            <pose relative_to='__model__'/>
            <parent>__model__</parent>
            <child>rgbd_camera</child>
        </joint>

        <joint name='left_wheel_joint_r0' type='revolute'> <!--continous joint is not supported yet-->
            <pose relative_to='left_wheel_r0'/>
            <parent>chassis_r0</parent>
            <child>left_wheel_r0</child>
            <axis>
                <xyz expressed_in='__model__'>0 1 0</xyz> <!--can be defined as any frame or even arbitrary frames-->
                <limit>
                    <lower>-1.79769e+308</lower>    <!--negative infinity-->
                    <upper>1.79769e+308</upper>     <!--positive infinity-->
                </limit>
            </axis>
        </joint>

        <joint name='right_wheel_joint_r0' type='revolute'>
            <pose relative_to='right_wheel_r0'/>
            <parent>chassis_r0</parent>
            <child>right_wheel_r0</child>
            <axis>
                <xyz expressed_in='__model__'>0 1 0</xyz>
                <limit>
                    <lower>-1.79769e+308</lower>    <!--negative infinity-->
                    <upper>1.79769e+308</upper>     <!--positive infinity-->
                </limit>
            </axis>
        </joint>

        <!--different type of joints ball joint--> <!--defult value is the child-->
        <joint name='caster_wheel_r0' type='ball'>
            <parent>chassis_r0</parent>
            <child>caster_r0</child>
        </joint>
        <!--diff drive plugin--> <!--<topic>/model/vehicle_blue/cmd_vel</topic>-->
        <plugin
            filename="gz-sim-diff-drive-system"
            name="gz::sim::systems::DiffDrive">
            <left_joint>left_wheel_joint_r0</left_joint>
            <right_joint>right_wheel_joint_r0</right_joint>
            <wheel_separation>1.2</wheel_separation>
            <wheel_radius>0.4</wheel_radius>
            <odom_publish_frequency>1</odom_publish_frequency>
            <!--<topic>/model/vehicle_blue/cmd_vel</topic>-->
        </plugin>
    </model>



    <!-- </world> -->
</sdf>